Workbook
Name _Toc536378868: 'Building Component'!$E$6
Name _Toc536378869: 'Building Component'!$F$6
Name _Toc536378870: 'Building Component'!$I$6
Name _Toc536378871: 'Building Component'!$L$6
Name _Toc536378872: 'Building Component'!$O$6
Name _Toc536378873: 'Building Component'!$R$6
Name _Toc536378874: 'Building Component'!$U$6
Name _Toc536378875: 'Building Component'!$F$7
Name _Toc536378876: 'Building Component'!$G$7
Name _Toc536378877: 'Building Component'!$H$7
Name _Toc536378878: 'Building Component'!$I$7
Name _Toc536378879: 'Building Component'!$J$7
Name _Toc536378880: 'Building Component'!$K$7
Name _Toc536378881: 'Building Component'!$L$7
Name _Toc536378882: 'Building Component'!$M$7
Name _Toc536378883: 'Building Component'!$N$7
Name _Toc536378884: 'Building Component'!$O$7
Name _Toc536378885: 'Building Component'!$P$7
Name _Toc536378886: 'Building Component'!$Q$7
Name _Toc536378887: 'Building Component'!$R$7
Name _Toc536378888: 'Building Component'!$S$7
Name _Toc536378889: 'Building Component'!$T$7
Name _Toc536378890: 'Building Component'!$U$7
Name _Toc536378891: 'Building Component'!$V$7
Name _Toc536378892: 'Building Component'!$W$7
Name _Toc536378893: 'Building Component'!$E$17
Name _Toc536378894: 'Building Component'!$F$17
Name _Toc536378895: 'Building Component'!$G$17
Name _Toc536378896: 'Building Component'!$H$17
Name _Toc536378897: 'Building Component'!$I$17
Name _Toc536378898: 'Building Component'!$J$17
Name _Toc536378899: 'Building Component'!$K$17
Name _Toc536378900: 'Building Component'!$L$17
Name _Toc536378901: 'Building Component'!$M$17
Name _Toc536378902: 'Building Component'!$N$17
Name _Toc536378903: 'Building Component'!$O$17
Name _Toc536378904: 'Building Component'!$P$17
Name _Toc536378905: 'Building Component'!$Q$17
Name _Toc536378906: 'Building Component'!$R$17
Name _Toc536378907: 'Building Component'!$S$17
Name _Toc536378908: 'Building Component'!$T$17
Name _Toc536378909: 'Building Component'!$U$17
Name _Toc536378910: 'Building Component'!$V$17
Name _Toc536378911: 'Building Component'!$W$17
Name _Toc536378912: 'Building Component'!$E$18
Name _Toc536378913: 'Building Component'!$F$18
Name _Toc536378914: 'Building Component'!$G$18
Name _Toc536378915: 'Building Component'!$H$18
Name _Toc536378916: 'Building Component'!$I$18
Name _Toc536378917: 'Building Component'!$J$18
Name _Toc536378918: 'Building Component'!$K$18
Name _Toc536378919: 'Building Component'!$L$18
Name _Toc536378920: 'Building Component'!$M$18
Name _Toc536378921: 'Building Component'!$N$18
Name _Toc536378922: 'Building Component'!$O$18
Name _Toc536378923: 'Building Component'!$P$18
Name _Toc536378924: 'Building Component'!$Q$18
Name _Toc536378925: 'Building Component'!$R$18
Name _Toc536378926: 'Building Component'!$S$18
Name _Toc536378927: 'Building Component'!$T$18

Sheet Location (2)
B1: Abirhajira
B2: A) Residential
B3: Plot Grade | C3: Up to 200 | D3: 201 - 400 | E3: 401-600 | F3: 601-800 | G3: 801-1,000 | H3: 1,001-1,500 | I3: 1,501-2,000 | J3: 2,001-3,000 | K3: 3001-5000 | L3: 5,001-10,000 | M3: ≥10,001
B4: 1st | C4: 1066 | D4: 800 | E4: 600 | F4: 450 | G4: 338 | H4: 252 | I4: 190 | J4: 142 | K4: 106 | L4: 80 | M4: 60
B5: 2nd | C5: 648 | D5: 486 | E5: 364 | F5: 274 | G5: 206 | H5: 154 | I5: 116 | J5: 86 | K5: 64 | L5: 48 | M5: 36
B6: 3rd | C6: 416 | D6: 312 | E6: 234 | F6: 176 | G6: 132 | H6: 98 | I6: 74 | J6: 56 | K6: 42 | L6: 32 | M6: 24
B7: 4th | C7: NOT APPLICABLE
B9: B) Commercial
B10: Plot Grade | C10: Up to 200 | D10: 201 - 400 | E10: 401-600 | F10: 601-800 | G10: 801-1,000 | H10: 1,001-1,500 | I10: 1,501-2,000 | J10: 2,001-3,000 | K10: 3001-5000 | L10: 5,001-10,000 | M10: ≥10,001
B11: 1st | C11: 1600 | D11: 1200 | E11: 900 | F11: 674 | G11: 506 | H11: 380 | I11: 284 | J11: 214 | K11: 160 | L11: 120 | M11: 90
B12: 2nd | C12: 972 | D12: 730 | E12: 546 | F12: 410 | G12: 308 | H12: 230 | I12: 172 | J12: 130 | K12: 98 | L12: 72 | M12: 54
B13: 3rd | C13: 624 | D13: 468 | E13: 352 | F13: 264 | G13: 198 | H13: 148 | I13: 112 | J13: 84 | K13: 62 | L13: 46 | M13: 36
B14: 4th | C14: NOT APPLICABLE
B16: Adama
B17: A) Residential
B18: Plot Grade | C18: Up to 200 | D18: 201 - 400 | E18: 401-600 | F18: 601-800 | G18: 801-1,000 | H18: 1,001-1,500 | I18: 1,501-2,000 | J18: 2,001-3,000 | K18: 3001-5000 | L18: 5,001-10,000 | M18: ≥10,001
B19: 1st | C19: 13750 | D19: 10312.5 | E19: 7735 | F19: 5800 | G19: 4350 | H19: 3262.5 | I19: 2447.5 | J19: 1835 | K19: 1377.5 | L19: 1032.5 | M19: 775
B20: 2nd | C20: 13000 | D20: 9750 | E20: 7312.5 | F20: 5485 | G20: 4112.5 | H20: 3085 | I20: 2312.5 | J20: 1735 | K20: 1302.5 | L20: 975 | M20: 732.5
B21: 3rd | C21: 12250 | D21: 9187.5 | E21: 6890 | F21: 5167.5 | G21: 3875 | H21: 2907.5 | I21: 2180 | J21: 1635 | K21: 1227.5 | L21: 920 | M21: 690
B22: 4th | C22: 11500 | D22: 8625 | E22: 6470 | F22: 4852.5 | G22: 3637.5 | H22: 2730 | I22: 2047.5 | J22: 1535 | K22: 1152.5 | L22: 862.5 | M22: 647.5
B24: B) Commercial
B25: Plot Grade | C25: Up to 200 | D25: 201 - 400 | E25: 401-600 | F25: 601-800 | G25: 801-1,000 | H25: 1,001-1,500 | I25: 1,501-2,000 | J25: 2,001-3,000 | K25: 3001-5000 | L25: 5,001-10,000 | M25: ≥10,001
B26: 1st | C26: 16250 | D26: 12187.5 | E26: 9140 | F26: 6855 | G26: 5142.5 | H26: 3855 | I26: 2892.5 | J26: 2170 | K26: 1627.5 | L26: 1220 | M26: 915
B27: 2nd | C27: 15375 | D27: 11532.5 | E27: 8647.5 | F27: 6487.5 | G27: 4865 | H27: 3647.5 | I27: 2737.5 | J27: 2052.5 | K27: 1540 | L27: 1155 | M27: 865
B28: 3rd | C28: 14500 | D28: 10875 | E28: 8157.5 | F28: 6117.5 | G28: 4587.5 | H28: 3440 | I28: 2580 | J28: 1935 | K28: 1452.5 | L28: 1087.5 | M28: 817.5
B29: 4th | C29: 13625 | D29: 10220 | E29: 7665 | F29: 5747.5 | G29: 4310 | H29: 3232.5 | I29: 2425 | J29: 1817.5 | K29: 1365 | L29: 1022.5 | M29: 767.5
B31: Addis Zemen
B32: A) Residential | P32: =4*200 -> 800
B33: Plot Grade | C33: Up to 200 | D33: 201 - 400 | E33: 401-600 | F33: 601-800 | G33: 801-1,000 | H33: 1,001-1,500 | I33: 1,501-2,000 | J33: 2,001-3,000 | K33: 3001-5000 | L33: 5,001-10,000 | M33: ≥10,001 | P33: =4500+P32 -> 5300
B34: 1st | C34: 3666 | D34: 2750 | E34: 2062 | F34: 1546 | G34: 1160 | H34: 870 | I34: 652 | J34: 490 | K34: 368 | L34: 276 | M34: 206
B35: 2nd | C35: 2460 | D35: 1846 | E35: 1384 | F35: 1038 | G35: 778 | H35: 584 | I35: 438 | J35: 328 | K35: 246 | L35: 184 | M35: 138
B36: 3rd | C36: 1652 | D36: 1238 | E36: 930 | F36: 696 | G36: 522 | H36: 392 | I36: 294 | J36: 220 | K36: 166 | L36: 124 | M36: 94 | O36: =14000 -> 14000 | P36: =1400*3 -> 4200
B37: 4th | C37: NOT APPLICABLE | O37: 12000 | P37: =P36+1400 -> 5600
O38: =O36+O37 -> 26000 | P38: =P37*2 -> 11200
B39: B) Commercial
B40: Plot Grade | C40: Up to 200 | D40: 201 - 400 | E40: 401-600 | F40: 601-800 | G40: 801-1,000 | H40: 1,001-1,500 | I40: 1,501-2,000 | J40: 2,001-3,000 | K40: 3001-5000 | L40: 5,001-10,000 | M40: ≥10,001 | O40: =196 -> 196 | P40: =180 -> 180 | Q40: =O40*P40 -> 35280
B41: 1st | C41: 5500 | D41: 4124 | E41: 3094 | F41: 2320 | G41: 1740 | H41: 1306 | I41: 978 | J41: 734 | K41: 550 | L41: 412 | M41: 310 | O41: 24 | P41: 190 | Q41: =O41*P41 -> 4560
B42: 2nd | C42: 3692 | D42: 2768 | E42: 2076 | F42: 1558 | G42: 1168 | H42: 876 | I42: 656 | J42: 492 | K42: 370 | L42: 278 | M42: 208 | Q42: =Q40+Q41 -> 39840
B43: 3rd | C43: 2478 | D43: 1858 | E43: 1394 | F43: 1046 | G43: 784 | H43: 588 | I43: 442 | J43: 330 | K43: 248 | L43: 186 | M43: 140 | Q43: =Q42/2 -> 19920 | R43: =17000+25000 -> 42000
B44: 4th | C44: NOT APPLICABLE | Q44: =17000+Q43 -> 36920
...

Sheet Sheet1
A1: Ranges of Replacement cost rates for properties located in Addis Ababa
A2: Building Types | B2: Range of replacement cost rate | D2: Range used only for management purpose | F2: The diffrence
B3: Max | C3: Min | D3: Max | E3: Min | F3: Max | G3: Min | H3: Remark
A4: G+1 and G+2 | B4: ='G+ Buildings'!D166 -> 18745.139 | C4: ='G+ Buildings'!E166 -> 11081.785 | D4: 15582 | E4: 7588 | F4: =B4-D4 -> 3163.1388 | G4: =C4-E4 -> 3493.7846 | H4: Birr/m²
A5: G+3 and G+4 | B5: ='G+ Buildings'!I166 -> 16537.649 | C5: ='G+ Buildings'!J166 -> 11107.469 | D5: 16618 | E5: 9170 | F5: =B5-D5 -> -80.3506 | G5: =C5-E5 -> 1937.4688 | H5: Birr/m²
A6: G+5 and G+6 | B6: ='G+ Buildings'!N166 -> 16167.256 | C6: ='G+ Buildings'!O166 -> 11070.97 | D6: 17122 | E6: 8680 | F6: =B6-D6 -> -954.7438 | G6: =C6-E6 -> 2390.9702 | H6: Birr/m²
A7: G+7 and G+8 | B7: ='G+ Buildings'!S166 -> 19888.762 | C7: ='G+ Buildings'!T166 -> 11065.563 | D7: 16660 | E7: 12292 | F7: =B7-D7 -> 3228.7616 | G7: =C7-E7 -> -1226.437 | H7: Birr/m²
A8: G+9 and G+10 | B8: ='G+ Buildings'!X166 -> 13517.728 | C8: ='G+ Buildings'!Y166 -> 10670.837 | F8: =B8-D8 -> 13517.728 | G8: =C8-E8 -> 10670.837 | H8: Birr/m²
A9: G+11 to G+16 | B9: ='G+ Buildings'!AC166 -> 16584.962 | C9: ='G+ Buildings'!AD166 -> 10918.217 | F9: =B9-D9 -> 16584.962 | G9: =C9-E9 -> 10918.217 | H9: Birr/m²
A10: G+17 to G+22 | B10: ='G+ Buildings'!AH166 -> 16455.19 | C10: ='G+ Buildings'!AI166 -> 11022.305 | F10: =B10-D10 -> 16455.19 | G10: =C10-E10 -> 11022.305 | H10: Birr/m²
A11: G+23 and above | B11: ='G+ Buildings'!AM166 -> 16725.55 | C11: ='G+ Buildings'!AN166 -> 10946.605 | F11: =B11-D11 -> 16725.55 | G11: =C11-E11 -> 10946.605 | H11: Birr/m²
A12: Villa Higher | B12: ='Villa Higher'!D178 -> 25555.453 | C12: ='Villa Higher'!E178 -> 7776.2408 | D12: 16245 | E12: 3976 | F12: =B12-D12 -> 9310.4528 | G12: =C12-E12 -> 3800.2408 | H12: Birr/m²
A13: Lower Villa | B13: ='Villa Lower'!E62 -> 8862.0375 | C13: ='Villa Lower'!G62 -> 1510.004 | D13: 4032 | E13: 1694 | F13: =B13-D13 -> 4830.0375 | G13: =C13-E13 -> -183.996 | H13: Birr/m²
A14: Multipurpose Halls H<= 4m | B14: ='Multi-Purposed halls'!D151 -> 59422.793 | C14: ='Multi-Purposed halls'!E151 -> 11724.093 | D14: 9604 | E14: 1694 | F14: =B14-D14 -> 49818.793 | G14: =C14-E14 -> 10030.093 | H14: Birr/m²
A15: H=4.5 | B15: ='Multi-Purposed halls'!H151 -> 17215.99 | C15: ='Multi-Purposed halls'!I151 -> 3344.6534 | D15: 4732 | E15: 378 | F15: =B15-D15 -> 12483.99 | G15: =C15-E15 -> 2966.6534 | H15: Birr/m²
A16: H=5.5 | B16: ='Multi-Purposed halls'!L151 -> 1785.288 | C16: ='Multi-Purposed halls'!M151 -> 486.212 | D16: 1705 | E16: 196 | F16: =B16-D16 -> 80.288 | G16: =C16-E16 -> 290.212 | H16: Birr/m³
A17: H=6.5 | B17: ='Multi-Purposed halls'!P151 -> 1578.3152 | C17: ='Multi-Purposed halls'!Q151 -> 425.5908 | F17: =B17-D17 -> 1578.3152 | G17: =C17-E17 -> 425.5908 | H17: Birr/m³
A18: H=7.5 | B18: ='Multi-Purposed halls'!T151 -> 1364.851 | C18: ='Multi-Purposed halls'!U151 -> 359.7115 | D18: 1324 | E18: 154 | F18: =B18-D18 -> 40.851 | G18: =C18-E18 -> 205.7115 | H18: Birr/m³
A19: H=8.5 | B19: ='Multi-Purposed halls'!X151 -> 1297.5762 | C19: ='Multi-Purposed halls'!Y151 -> 331.9023 | F19: =B19-D19 -> 1297.5762 | G19: =C19-E19 -> 331.9023 | H19: Birr/m³
A20: H=10.5 | B20: ='Multi-Purposed halls'!AB151 -> 1178.378 | C20: ='Multi-Purposed halls'!AC151 -> 310.957 | D20: 1113 | E20: 154 | F20: =B20-D20 -> 65.378 | G20: =C20-E20 -> 156.957 | H20: Birr/m³
A21: H=11.5 | B21: ='Multi-Purposed halls'!AF151 -> 1127.794 | C21: ='Multi-Purposed halls'!AG151 -> 293.261 | F21: =B21-D21 -> 1127.794 | G21: =C21-E21 -> 293.261 | H21: Birr/m³

Sheet Villa Lower
A2: ITEM NO. | B2: Building components
A3: 1 | B3: Foundation | C3: Factors | E3: Max | G3: Min
B4: 1.1 Earth Work But no cart away | C4: 1 | E4: =MAX(C4:C7) -> 47.16 | F4: =MAX(D4:D7) -> 0 | G4: =MIN(C4:C7) -> 1 | I4: =$C4*H4/100 -> 0
B5: 1.2 Earth Work Foundation & cart away | C5: 4 | H5: 100 | I5: =$C5*H5/100 -> 4
B6: 1.3 Earth Work Foundation, hardcore, mass concrete, stone masonry | C6: 20.49 | I6: =$C6*H6/100 -> 0
B7: 1.4 Earth Work Foundation, hardcore, mass concrete, stone masonry BGL & AGL | C7: 47.16 | I7: =$C7*H7/100 -> 0
A8: 2 | B8: Structure | I8: =$C8*H8/100 -> 0
A9: 3 | B9: Block Work (Internal) | I9: =$C9*H9/100 -> 0
B10: 3.1 Chicka | C10: 2.16 | E10: =MAX(C10:C13) -> 10.63 | F10: =MAX(D10:D13) -> 0 | G10: =MIN(C10:C14) -> 1 | I10: =$C10*H10/100 -> 0
B11: 3.2 Poor Chika | C11: 1 | I11: =$C11*H11/100 -> 0
B12: 3.3 HCB but no R.C structure and plastering | C12: 10.63 | H12: 100 | I12: =$C12*H12/100 -> 10.63
B13: 3.4 Stone masonry with cement-chicka mortar mix | C13: 8.4 | I13: =$C13*H13/100 -> 0
B14: 3.5 CIS Wall | C14: 1.89 | I14: =$C14*H14/100 -> 0
A15: 4 | B15: Block Work (External) | I15: =$C15*H15/100 -> 0
B16: 4.1 Chicka | C16: 2.16 | E16: =MAX(C16:C20) -> 10.63 | F16: =MAX(D16:D20) -> 0 | G16: =MIN(C16:C20) -> 1 | I16: =$C16*H16/100 -> 0
B17: 4.2 Poor Chika | C17: 1 | I17: =$C17*H17/100 -> 0
B18: 4.3 HCB but no R.C structure and plastering | C18: 10.63 | H18: 100 | I18: =$C18*H18/100 -> 10.63
B19: 4.4 Stone masonry with cement-chicka mortar mix | C19: 8.4 | I19: =$C19*H19/100 -> 0
B20: 4.5 CIS Wall | C20: 1.89 | I20: =$C20*H20/100 -> 0
A21: 5 | B21: Roofing | I21: =$C21*H21/100 -> 0
B22: 5.1 CIS G-35 on wood | C22: 1 | E22: =MAX(C22:C24) -> 1.62 | F22: =MAX(D22:D24) -> 0 | G22: =MIN(C22:C24) -> 1 | H22: 100 | I22: =$C22*H22/100 -> 1
B23: 5.2 CIS G-32 on wood | C23: 1.37 | I23: =$C23*H23/100 -> 0
B24: 5.3 CIS G-30 on wood | C24: 1.62 | I24: =$C24*H24/100 -> 0
A25: 6 | B25: Joinery | I25: =$C25*H25/100 -> 0
B26: 6.1 Internal wooden door made of Low quality wood | C26: 1.67 | E26: =MAX(C26:C27) -> 1.67 | F26: =MAX(D26:D27) -> 0 | G26: =MIN(C26:C27) -> 1 | I26: =$C26*H26/100 -> 0
B27: 6.2 As item No.1 above but made of Poor Quality wood | C27: 1 | I27: =$C27*H27/100 -> 0
A28: 7 | B28: Metal Works | I28: =$C28*H28/100 -> 0
B29: 7.1 LTZ or RHS | C29: 1 | E29: =MAX(C29) -> 1 | F29: =MAX(D29) -> 0 | G29: =MIN(C29:C30) -> 1 | H29: 100 | I29: =$C29*H29/100 -> 1
A30: 8 | B30: Floor Finish | I30: =$C30*H30/100 -> 0
B31: 8.1 Cement Screed | C31: 1 | E31: =MAX(C31:C34) -> 6.49 | F31: =MAX(D31:D34) -> 0 | G31: =MIN(C31:C34) -> 1 | H31: 100 | I31: =$C31*H31/100 -> 1
B32: 8.2 Cement Tile | C32: 2.72 | I32: =$C32*H32/100 -> 0
B33: 8.3 Terrazzo | C33: 3.06 | I33: =$C33*H33/100 -> 0
B34: 8.4 Poor quality wooden | C34: 6.49 | I34: =$C34*H34/100 -> 0
A35: 9 | B35: Wall Finish (Internal) | I35: =$C35*H35/100 -> 0
B36: 9.1 Pointed HCB | C36: 1 | E36: =MAX(C36:C39) -> 4.04 | F36: =MAX(D36:D39) -> 0 | G36: =MIN(C36:C39) -> 1 | H36: 100 | I36: =$C36*H36/100 -> 1
B37: 9.2 Painted | C37: 1.08 | I37: =$C37*H37/100 -> 0
B38: 9.3 Plastered | C38: 2.96 | I38: =$C38*H38/100 -> 0
B39: 9.4 Plastering & Painting | C39: 4.04 | I39: =$C39*H39/100 -> 0
A40: 10 | B40: Wall Finish (External) | I40: =$C40*H40/100 -> 0
B41: 10.1 Pointed HCB | C41: 1 | E41: =MAX(C41:C48) -> 13.32 | F41: =MAX(D41:D48) -> 0 | G41: =MIN(C41:C48) -> 1 | H41: 100 | I41: =$C41*H41/100 -> 1
...

Sheet Villa Higher
A2: ITEM NO. | B2: Building components
A3: 1 | B3: Foundation | C3: Factors | D3: Max | E3: Min
B4: 1.1 Foundation Work in: Earthwortk,Hard-core,Mass concrete floor with C-15,Stone masnory AGL and BGL | C4: 1.31 | D4: =MAX(C4:C8) -> 8.3 | E4: =MIN(C4:C8) -> 1.31 | G4: =$C4*F4/100 -> 0
B5: 1.2 Foundation work as Item No.1 above but with mass concrete of higher class (c-20) | C5: 1.48 | G5: =$C5*F5/100 -> 0
B6: 1.3 Foundation work as Item No.2 above but with R.C. grade beam | C6: 2.85 | G6: =$C6*F6/100 -> 0
B7: 1.4 Foundation work as Item No.1 above but with R.C. floor slab and R.C grade beam | C7: 5.53 | G7: =$C7*F7/100 -> 0
B8: 1.4 Foundation work as Item No.4 above but with R.C. foundation column and R.C Footing | C8: 8.3 | F8: 100 | G8: =$C8*F8/100 -> 8.3
A9: 2 | B9: Structure | G9: =$C9*F9/100 -> 0
B10: 2.1 Structure for mud and CIS-on- wooden walls | D10: =MAX(C10:C12) -> 9.19 | E10: =MIN(C10:C12) -> 4.2 | G10: =$C10*F10/100 -> 0
B11: 2.2 .R.C structure (Elevation colums and tie beam) | C11: 4.2 | F11: 100 | G11: =$C11*F11/100 -> 4.2
B12: 2.3 As item no.2 above but for R.C roof slab | C12: 9.19 | G12: =$C12*F12/100 -> 0
A13: 3 | B13: Block Work | G13: =$C13*F13/100 -> 0
B14: 3.1 Internal | G14: =$C14*F14/100 -> 0
B15: 3.1.1 Chicka | C15: 0.48 | D15: =MAX(C15:C26) -> 6.92 | E15: =MIN(C15:C38) -> 0.48 | G15: =$C15*F15/100 -> 0
B16: 3.1.2 CIS G-32 | C16: 0.75 | G16: =$C16*F16/100 -> 0
B17: 3.1.3 CIS G-30 | C17: 0.71 | G17: =$C17*F17/100 -> 0
B18: 3.1.4 CIS G-28 | C18: 0.96 | G18: =$C18*F18/100 -> 0
B19: 3.1.5 HCB 15 cm thick | C19: 0.69 | F19: 100 | G19: =$C19*F19/100 -> 0.69
B20: 3.1.6 Brick 12cm thick | C20: 2.2 | G20: =$C20*F20/100 -> 0
B21: 3.1.7 stone 40cm thick | C21: 1.21 | G21: =$C21*F21/100 -> 0
B22: 3.1.8 Chip wood-double | C22: 1.03 | G22: =$C22*F22/100 -> 0
B23: 3.1.9 Alumimium | C23: 6.92 | G23: =$C23*F23/100 -> 0
B24: 3.1.10 HCB 10 cm thick | C24: 0.55 | G24: =$C24*F24/100 -> 0
B25: 3.1.11 Hard board fixed to zigba frame (one face) | C25: 0.65 | G25: =$C25*F25/100 -> 0
B26: 3.1.12 Ditto as above but both side coverd | C26: 1.12 | G26: =$C26*F26/100 -> 0
B27: 3.2 External | G27: =$C27*F27/100 -> 0
B28: 3.2.1 Chicka | C28: 0.93 | D28: =MAX(C28:C38) -> 18.59 | E28: =MIN(C28:C38) -> 0.93 | G28: =$C28*F28/100 -> 0
B29: 3.2.2 CIS G-32 | C29: 1.44 | G29: =$C29*F29/100 -> 0
B30: 3.2.3 CIS G-30 | C30: 1.37 | G30: =$C30*F30/100 -> 0
B31: 3.2.4 CIS G-28 | C31: 1.86 | G31: =$C31*F31/100 -> 0
B32: 3.2.5 EGA on steel | C32: 2.33 | G32: =$C32*F32/100 -> 0
B33: 3.2.6 HCB 20 cm thick | C33: 1.35 | F33: 100 | G33: =$C33*F33/100 -> 1.35
B34: 3.2.7 Brick 25cm thick | C34: 8.71 | G34: =$C34*F34/100 -> 0
B35: 3.2.8 stone 40cm thick | C35: 2.34 | G35: =$C35*F35/100 -> 0
B36: 3.2.9 stone 50cm thick | C36: 2.93 | G36: =$C36*F36/100 -> 0
B37: 3.2.10 Alumimium | C37: 13.8 | G37: =$C37*F37/100 -> 0
B38: 3.2.11 Curtin wall made with special frame & 4mm cored polycarbonate treated against UV rail | C38: 18.59 | G38: =$C38*F38/100 -> 0
A39: 4 | B39: Roofing | G39: =$C39*F39/100 -> 0
B40: 4.1 CIS G-32 on wood | C40: 1.6 | D40: =MAX(C40:C54) -> 4.98 | E40: =MIN(C40:C54) -> 1.6 | G40: =$C40*F40/100 -> 0
B41: 4.2 CIS G-30 on wood | C41: 1.61 | G41: =$C41*F41/100 -> 0
...

Sheet G+ Buildings
A2: ITEM NO. | B2: Building components
A3: 1 | B3: Foundation | C3: Factors | H3: Factors | M3: Factors | R3: Factors | W3: Factors | AB3: Factors | AG3: Factors | AL3: Factors
C4: G+1 & G+2 | H4: G+3 & G+4 | M4: G+5 & G+6 | R4: G+7 & G+8 | W4: G+9 & G+10 | AB4: G+11 to G+16 | AG4: G+17 to G+22 | AL4: G+23 & Above
D5: Max | E5: Min | I5: Max | J5: Min | N5: Max | O5: Min | S5: Max | T5: Min | X5: Max | Y5: Min | AC5: Max | AD5: Min | AH5: Max | AI5: Min | AM5: Max | AN5: Min
B6: 1.1 Foundation | C6: 4.99 | D6: =MAX(C6) -> 4.99 | E6: =MIN(C6) -> 4.99 | F6: 100 | G6: =$C6*F6/100 -> 4.99 | H6: 4.53 | I6: =MAX(H6) -> 4.53 | J6: =MIN(H6) -> 4.53 | L6: =$H6*K6/100 -> 0 | M6: 5.78 | N6: =MAX(M6) -> 5.78 | O6: =MIN(M6) -> 5.78 | Q6: =$M6*P6/100 -> 0 | R6: 3.29 | S6: =MAX(R6) -> 3.29 | T6: =MIN(R6) -> 3.29 | V6: =$R6*U6/100 -> 0 | W6: 4.61 | X6: =MAX(W6) -> 4.61 | Y6: =MIN(W6) -> 4.61 | AA6: =$W6*Z6/100 -> 0 | AB6: 3.72 | AC6: =MAX(AB6) -> 3.72 | AD6: =MIN(AB6) -> 3.72 | AF6: =$AB6*AE6/100 -> 0 | AG6: 4.9 | AH6: =MAX(AG6) -> 4.9 | AI6: =MIN(AG6) -> 4.9 | AK6: =$AG6*AJ6/100 -> 0 | AL6: 4.03 | AM6: =MAX(AL6) -> 4.03 | AN6: =MIN(AL6) -> 4.03 | AP6: =$AL6*AO6/100 -> 0
A7: 2 | B7: Structure | G7: =$C7*F7/100 -> 0 | L7: =$H7*K7/100 -> 0 | Q7: =$M7*P7/100 -> 0 | V7: =$R7*U7/100 -> 0 | AA7: =$W7*Z7/100 -> 0 | AF7: =$AB7*AE7/100 -> 0 | AK7: =$AG7*AJ7/100 -> 0 | AP7: =$AL7*AO7/100 -> 0
B8: 2.1 .R.C structure (Elevation colums and suspended beam) | C8: 4.94 | D8: =MAX(C8) -> 4.94 | E8: =MIN(C8) -> 4.94 | F8: 100 | G8: =$C8*F8/100 -> 4.94 | H8: 6.96 | I8: =MAX(H8) -> 6.96 | J8: =MIN(H8) -> 6.96 | L8: =$H8*K8/100 -> 0 | M8: 5.54 | N8: =MAX(M8) -> 5.54 | O8: =MIN(M8) -> 5.54 | Q8: =$M8*P8/100 -> 0 | R8: 5.75 | S8: =MAX(R8) -> 5.75 | T8: =MIN(R8) -> 5.75 | V8: =$R8*U8/100 -> 0 | W8: 4.01 | X8: =MAX(W8) -> 4.01 | Y8: =MIN(W8) -> 4.01 | AA8: =$W8*Z8/100 -> 0 | AB8: 6.85 | AC8: =MAX(AB8) -> 6.85 | AD8: =MIN(AB8) -> 6.85 | AF8: =$AB8*AE8/100 -> 0 | AG8: 7.16 | AH8: =MAX(AG8) -> 7.16 | AI8: =MIN(AG8) -> 7.16 | AK8: =$AG8*AJ8/100 -> 0 | AL8: 8.6 | AM8: =MAX(AL8) -> 8.6 | AN8: =MIN(AL8) -> 8.6 | AP8: =$AL8*AO8/100 -> 0
A9: 3 | B9: Block Work | G9: =$C9*F9/100 -> 0 | L9: =$H9*K9/100 -> 0 | Q9: =$M9*P9/100 -> 0 | V9: =$R9*U9/100 -> 0 | AA9: =$W9*Z9/100 -> 0 | AF9: =$AB9*AE9/100 -> 0 | AK9: =$AG9*AJ9/100 -> 0 | AP9: =$AL9*AO9/100 -> 0
B10: 3.1 Internal | G10: =$C10*F10/100 -> 0 | L10: =$H10*K10/100 -> 0 | Q10: =$M10*P10/100 -> 0 | V10: =$R10*U10/100 -> 0 | AA10: =$W10*Z10/100 -> 0 | AF10: =$AB10*AE10/100 -> 0 | AK10: =$AG10*AJ10/100 -> 0 | AP10: =$AL10*AO10/100 -> 0
B11: 3.1.1 HCB 15 cm thick | C11: 0.53 | D11: =MAX(C11:C17) -> 5.26 | E11: =MIN(C11:C17) -> 0.42 | F11: 100 | G11: =$C11*F11/100 -> 0.53 | H11: 0.43 | I11: =MAX(H11:H17) -> 4.31 | J11: =MIN(H11:H17) -> 0.34 | L11: =$H11*K11/100 -> 0 | M11: 0.29 | N11: =MAX(M11:M17) -> 2.95 | O11: =MIN(M11:M17) -> 0.23 | Q11: =$M11*P11/100 -> 0 | R11: 2.69 | S11: =MAX(R11:R17) -> 26.92 | T11: =MIN(R11:R17) -> 2.14 | V11: =$R11*U11/100 -> 0 | W11: 0.38 | X11: =MAX(W11:W17) -> 3.78 | Y11: =MIN(W11:W17) -> 0.3 | AA11: =$W11*Z11/100 -> 0 | AB11: 0.06 | AC11: =MAX(AB11:AB17) -> 0.61 | AD11: =MIN(AB11:AB17) -> 0.05 | AF11: =$AB11*AE11/100 -> 0 | AG11: 0.37 | AH11: =MAX(AG11:AG17) -> 3.72 | AI11: =MIN(AG11:AG17) -> 0.3 | AK11: =$AG11*AJ11/100 -> 0 | AL11: 0.24 | AM11: =MAX(AL11:AL17) -> 2.39 | AN11: =MIN(AL11:AL17) -> 0.19 | AP11: =$AL11*AO11/100 -> 0
B12: 3.1.2 Brick 12cm thick | C12: 1.68 | G12: =$C12*F12/100 -> 0 | H12: 1.37 | L12: =$H12*K12/100 -> 0 | M12: 0.94 | Q12: =$M12*P12/100 -> 0 | R12: 8.57 | V12: =$R12*U12/100 -> 0 | W12: 1.2 | AA12: =$W12*Z12/100 -> 0 | AB12: 0.2 | AF12: =$AB12*AE12/100 -> 0 | AG12: 1.19 | AK12: =$AG12*AJ12/100 -> 0 | AL12: 0.76 | AP12: =$AL12*AO12/100 -> 0
B13: 3.1.3 stone 40cm thick | C13: 0.92 | G13: =$C13*F13/100 -> 0 | H13: 0.75 | L13: =$H13*K13/100 -> 0 | M13: 0.52 | Q13: =$M13*P13/100 -> 0 | R13: 4.71 | V13: =$R13*U13/100 -> 0 | W13: 0.66 | AA13: =$W13*Z13/100 -> 0 | AB13: 0.11 | AF13: =$AB13*AE13/100 -> 0 | AG13: 0.65 | AK13: =$AG13*AJ13/100 -> 0 | AL13: 0.42 | AP13: =$AL13*AO13/100 -> 0
B14: 3.1.4 Chip wood-double | C14: 0.78 | G14: =$C14*F14/100 -> 0 | H14: 0.64 | L14: =$H14*K14/100 -> 0 | M14: 0.44 | Q14: =$M14*P14/100 -> 0 | R14: 4 | V14: =$R14*U14/100 -> 0 | W14: 0.56 | AA14: =$W14*Z14/100 -> 0 | AB14: 0.09 | AF14: =$AB14*AE14/100 -> 0 | AG14: 0.55 | AK14: =$AG14*AJ14/100 -> 0 | AL14: 0.36 | AP14: =$AL14*AO14/100 -> 0
B15: 3.1.5 Alumimium | C15: 5.26 | G15: =$C15*F15/100 -> 0 | H15: 4.31 | L15: =$H15*K15/100 -> 0 | M15: 2.95 | Q15: =$M15*P15/100 -> 0 | R15: 26.92 | V15: =$R15*U15/100 -> 0 | W15: 3.78 | AA15: =$W15*Z15/100 -> 0 | AB15: 0.61 | AF15: =$AB15*AE15/100 -> 0 | AG15: 3.72 | AK15: =$AG15*AJ15/100 -> 0 | AL15: 2.39 | AP15: =$AL15*AO15/100 -> 0
B16: 3.1.6 HCB 10 cm thick | C16: 0.42 | G16: =$C16*F16/100 -> 0 | H16: 0.34 | L16: =$H16*K16/100 -> 0 | M16: 0.23 | Q16: =$M16*P16/100 -> 0 | R16: 2.14 | V16: =$R16*U16/100 -> 0 | W16: 0.3 | AA16: =$W16*Z16/100 -> 0 | AB16: 0.05 | AF16: =$AB16*AE16/100 -> 0 | AG16: 0.3 | AK16: =$AG16*AJ16/100 -> 0 | AL16: 0.19 | AP16: =$AL16*AO16/100 -> 0
B17: 3.1.7 Magnesium/Gypsum Board | C17: 0.85 | G17: =$C17*F17/100 -> 0 | H17: 0.7 | L17: =$H17*K17/100 -> 0 | M17: 0.48 | Q17: =$M17*P17/100 -> 0 | R17: 4.36 | V17: =$R17*U17/100 -> 0 | W17: 0.61 | AA17: =$W17*Z17/100 -> 0 | AB17: 0.1 | AF17: =$AB17*AE17/100 -> 0 | AG17: 0.6 | AK17: =$AG17*AJ17/100 -> 0 | AL17: 0.39 | AP17: =$AL17*AO17/100 -> 0
B18: 3.2 External | G18: =$C18*F18/100 -> 0 | L18: =$H18*K18/100 -> 0 | Q18: =$M18*P18/100 -> 0 | V18: =$R18*U18/100 -> 0 | AA18: =$W18*Z18/100 -> 0 | AF18: =$AB18*AE18/100 -> 0 | AK18: =$AG18*AJ18/100 -> 0 | AP18: =$AL18*AO18/100 -> 0
B19: 3.2.1 HCB 20 cm thick | C19: 1.03 | D19: =MAX(C19:C25) -> 14.24 | E19: =MIN(C19:C25) -> 1.03 | F19: 100 | G19: =$C19*F19/100 -> 1.03 | H19: 0.58 | I19: =MAX(H19:H25) -> 8 | J19: =MIN(H19:H25) -> 0.58 | L19: =$H19*K19/100 -> 0 | M19: 0.29 | N19: =MAX(M19:M25) -> 4.05 | O19: =MIN(M19:M25) -> 0.29 | Q19: =$M19*P19/100 -> 0 | R19: 1.02 | S19: =MAX(R19:R25) -> 14.06 | T19: =MIN(R19:R25) -> 1.02 | V19: =$R19*U19/100 -> 0 | W19: 0.26 | X19: =MAX(W19:W25) -> 3.54 | Y19: =MIN(W19:W25) -> 0.26 | AA19: =$W19*Z19/100 -> 0 | AB19: 0.17 | AC19: =MAX(AB19:AB25) -> 2.34 | AD19: =MIN(AB19:AB25) -> 0.17 | AF19: =$AB19*AE19/100 -> 0 | AG19: 0.21 | AH19: =MAX(AG19:AG25) -> 2.82 | AI19: =MIN(AG19:AG25) -> 0.21 | AK19: =$AG19*AJ19/100 -> 0 | AL19: 0.91 | AM19: =MAX(AL19:AL25) -> 12.57 | AN19: =MIN(AL19:AL25) -> 0.91 | AP19: =$AL19*AO19/100 -> 0
B20: 3.2.2 Brick 25cm thick | C20: 6.67 | G20: =$C20*F20/100 -> 0 | H20: 3.75 | L20: =$H20*K20/100 -> 0 | M20: 1.9 | Q20: =$M20*P20/100 -> 0 | R20: 6.59 | V20: =$R20*U20/100 -> 0 | W20: 1.66 | AA20: =$W20*Z20/100 -> 0 | AB20: 1.1 | AF20: =$AB20*AE20/100 -> 0 | AG20: 1.32 | AK20: =$AG20*AJ20/100 -> 0 | AL20: 5.89 | AP20: =$AL20*AO20/100 -> 0
B21: 3.2.3 stone 40cm thick | C21: 1.8 | G21: =$C21*F21/100 -> 0 | H21: 1.01 | L21: =$H21*K21/100 -> 0 | M21: 0.51 | Q21: =$M21*P21/100 -> 0 | R21: 1.77 | V21: =$R21*U21/100 -> 0 | W21: 0.45 | AA21: =$W21*Z21/100 -> 0 | AB21: 0.3 | AF21: =$AB21*AE21/100 -> 0 | AG21: 0.36 | AK21: =$AG21*AJ21/100 -> 0 | AL21: 1.59 | AP21: =$AL21*AO21/100 -> 0
B22: 3.2.4 stone 50cm thick | C22: 2.24 | G22: =$C22*F22/100 -> 0 | H22: 1.26 | L22: =$H22*K22/100 -> 0 | M22: 0.64 | Q22: =$M22*P22/100 -> 0 | R22: 2.22 | V22: =$R22*U22/100 -> 0 | W22: 0.56 | AA22: =$W22*Z22/100 -> 0 | AB22: 0.37 | AF22: =$AB22*AE22/100 -> 0 | AG22: 0.45 | AK22: =$AG22*AJ22/100 -> 0 | AL22: 1.98 | AP22: =$AL22*AO22/100 -> 0
B23: 3.2.5 Alumimium | C23: 10.25 | G23: =$C23*F23/100 -> 0 | H23: 5.76 | L23: =$H23*K23/100 -> 0 | M23: 2.92 | Q23: =$M23*P23/100 -> 0 | R23: 10.13 | V23: =$R23*U23/100 -> 0 | W23: 2.55 | AA23: =$W23*Z23/100 -> 0 | AB23: 1.69 | AF23: =$AB23*AE23/100 -> 0 | AG23: 2.03 | AK23: =$AG23*AJ23/100 -> 0 | AL23: 9.05 | AP23: =$AL23*AO23/100 -> 0
B24: 3.2.6 Magnesium/Gypsum Board | C24: 1.66 | G24: =$C24*F24/100 -> 0 | H24: 0.93 | L24: =$H24*K24/100 -> 0 | M24: 0.47 | Q24: =$M24*P24/100 -> 0 | R24: 1.64 | V24: =$R24*U24/100 -> 0 | W24: 0.41 | AA24: =$W24*Z24/100 -> 0 | AB24: 0.27 | AF24: =$AB24*AE24/100 -> 0 | AG24: 0.33 | AK24: =$AG24*AJ24/100 -> 0 | AL24: 1.47 | AP24: =$AL24*AO24/100 -> 0
B25: 3.2.7 Curtin wall made with special frame & 4mm cored polycarbonate treated against UV rail | C25: 14.24 | G25: =$C25*F25/100 -> 0 | H25: 8 | L25: =$H25*K25/100 -> 0 | M25: 4.05 | Q25: =$M25*P25/100 -> 0 | R25: 14.06 | V25: =$R25*U25/100 -> 0 | W25: 3.54 | AA25: =$W25*Z25/100 -> 0 | AB25: 2.34 | AF25: =$AB25*AE25/100 -> 0 | AG25: 2.82 | AK25: =$AG25*AJ25/100 -> 0 | AL25: 12.57 | AP25: =$AL25*AO25/100 -> 0
A26: 4 | B26: Roofing | G26: =$C26*F26/100 -> 0 | L26: =$H26*K26/100 -> 0 | Q26: =$M26*P26/100 -> 0 | V26: =$R26*U26/100 -> 0 | AA26: =$W26*Z26/100 -> 0 | AF26: =$AB26*AE26/100 -> 0 | AK26: =$AG26*AJ26/100 -> 0 | AP26: =$AL26*AO26/100 -> 0
B27: 4.1 CIS G-32 on wood | C27: 1.8 | D27: =MAX(C27:C41) -> 6.5 | E27: =MIN(C27:C41) -> 1.32 | G27: =$C27*F27/100 -> 0 | H27: 0.7 | I27: =MAX(H27:H41) -> 4.13 | J27: =MIN(H27:H41) -> 0.56 | L27: =$H27*K27/100 -> 0 | M27: 0.4 | N27: =MAX(M27:M41) -> 4.59 | O27: =MIN(M27:M41) -> 0.3 | Q27: =$M27*P27/100 -> 0 | R27: 0.39 | S27: =MAX(R27:R41) -> 5.63 | T27: =MIN(R27:R41) -> 0.27 | V27: =$R27*U27/100 -> 0 | W27: 0.24 | X27: =MAX(W27:W41) -> 4.38 | Y27: =MIN(W27:W41) -> 0.17 | AA27: =$W27*Z27/100 -> 0 | AB27: 0.23 | AC27: =MAX(AB27:AB41) -> 24.05 | AD27: =MIN(AB27:AB41) -> 0.14 | AF27: =$AB27*AE27/100 -> 0 | AG27: 0.16 | AH27: =MAX(AG27:AG41) -> 9.57 | AI27: =MIN(AG27:AG41) -> 0.14 | AK27: =$AG27*AJ27/100 -> 0 | AL27: 0.08 | AM27: =MAX(AL27:AL41) -> 8.57 | AN27: =MIN(AL27:AL41) -> 0.06 | AP27: =$AL27*AO27/100 -> 0
B28: 4.2 CIS G-30 on wood | C28: 1.81 | G28: =$C28*F28/100 -> 0 | H28: 0.7 | L28: =$H28*K28/100 -> 0 | M28: 0.4 | Q28: =$M28*P28/100 -> 0 | R28: 0.39 | V28: =$R28*U28/100 -> 0 | W28: 0.24 | AA28: =$W28*Z28/100 -> 0 | AB28: 0.23 | AF28: =$AB28*AE28/100 -> 0 | AG28: 0.16 | AK28: =$AG28*AJ28/100 -> 0 | AL28: 0.08 | AP28: =$AL28*AO28/100 -> 0
B29: 4.3 CIS G-28 on wood | C29: 2.04 | F29: 100 | G29: =$C29*F29/100 -> 2.04 | H29: 0.76 | L29: =$H29*K29/100 -> 0 | M29: 0.45 | Q29: =$M29*P29/100 -> 0 | R29: 0.45 | V29: =$R29*U29/100 -> 0 | W29: 0.27 | AA29: =$W29*Z29/100 -> 0 | AB29: 0.27 | AF29: =$AB29*AE29/100 -> 0 | AG29: 0.17 | AK29: =$AG29*AJ29/100 -> 0 | AL29: 0.1 | AP29: =$AL29*AO29/100 -> 0
B30: 4.4 EGA on steel | C30: 2.64 | G30: =$C30*F30/100 -> 0 | H30: 0.67 | L30: =$H30*K30/100 -> 0 | M30: 0.38 | Q30: =$M30*P30/100 -> 0 | R30: 0.37 | V30: =$R30*U30/100 -> 0 | W30: 0.23 | AA30: =$W30*Z30/100 -> 0 | AB30: 0.21 | AF30: =$AB30*AE30/100 -> 0 | AG30: 0.16 | AK30: =$AG30*AJ30/100 -> 0 | AL30: 0.08 | AP30: =$AL30*AO30/100 -> 0
B31: 4.5 EGA on wood | C31: 1.72 | G31: =$C31*F31/100 -> 0 | H31: 0.67 | L31: =$H31*K31/100 -> 0 | M31: 0.38 | Q31: =$M31*P31/100 -> 0 | R31: 0.37 | V31: =$R31*U31/100 -> 0 | W31: 0.23 | AA31: =$W31*Z31/100 -> 0 | AB31: 0.21 | AF31: =$AB31*AE31/100 -> 0 | AG31: 0.16 | AK31: =$AG31*AJ31/100 -> 0 | AL31: 0.08 | AP31: =$AL31*AO31/100 -> 0
B32: 4.6 CIS G-28 on steel | C32: 2.76 | G32: =$C32*F32/100 -> 0 | H32: 0.67 | L32: =$H32*K32/100 -> 0 | M32: 0.38 | Q32: =$M32*P32/100 -> 0 | R32: 0.37 | V32: =$R32*U32/100 -> 0 | W32: 0.23 | AA32: =$W32*Z32/100 -> 0 | AB32: 0.21 | AF32: =$AB32*AE32/100 -> 0 | AG32: 0.16 | AK32: =$AG32*AJ32/100 -> 0 | AL32: 0.08 | AP32: =$AL32*AO32/100 -> 0
B33: 4.7 Cement roof tile | C33: 1.32 | G33: =$C33*F33/100 -> 0 | H33: 0.56 | L33: =$H33*K33/100 -> 0 | M33: 0.3 | Q33: =$M33*P33/100 -> 0 | R33: 0.27 | V33: =$R33*U33/100 -> 0 | W33: 0.18 | AA33: =$W33*Z33/100 -> 0 | AB33: 0.14 | AF33: =$AB33*AE33/100 -> 0 | AG33: 0.14 | AK33: =$AG33*AJ33/100 -> 0 | AL33: 0.06 | AP33: =$AL33*AO33/100 -> 0
B34: 4.8 R.C without water-proof material (Accessible) | C34: 4.97 | G34: =$C34*F34/100 -> 0 | H34: 2.93 | L34: =$H34*K34/100 -> 0 | M34: 1.04 | Q34: =$M34*P34/100 -> 0 | R34: 0.94 | V34: =$R34*U34/100 -> 0 | W34: 0.77 | AA34: =$W34*Z34/100 -> 0 | AB34: 0.77 | AF34: =$AB34*AE34/100 -> 0 | AG34: 0.77 | AK34: =$AG34*AJ34/100 -> 0 | AL34: 0.77 | AP34: =$AL34*AO34/100 -> 0
B35: 4.9 R.C without water-proof material (in Accessible) | C35: 4.72 | G35: =$C35*F35/100 -> 0 | H35: 2.86 | L35: =$H35*K35/100 -> 0 | M35: 1.02 | Q35: =$M35*P35/100 -> 0 | R35: 0.92 | V35: =$R35*U35/100 -> 0 | W35: 0.75 | AA35: =$W35*Z35/100 -> 0 | AB35: 0.75 | AF35: =$AB35*AE35/100 -> 0 | AG35: 0.75 | AK35: =$AG35*AJ35/100 -> 0 | AL35: 0.75 | AP35: =$AL35*AO35/100 -> 0
B36: 4.10 R.C with water-proof material (Accessible) | C36: 6.5 | G36: =$C36*F36/100 -> 0 | H36: 2.39 | L36: =$H36*K36/100 -> 0 | M36: 2.72 | Q36: =$M36*P36/100 -> 0 | R36: 1.48 | V36: =$R36*U36/100 -> 0 | W36: 0.25 | AA36: =$W36*Z36/100 -> 0 | AB36: 0.43 | AF36: =$AB36*AE36/100 -> 0 | AG36: 0.65 | AK36: =$AG36*AJ36/100 -> 0 | AL36: 0.36 | AP36: =$AL36*AO36/100 -> 0
B37: 4.11 R.C with water-proof material (in Accessible) | C37: 5.52 | G37: =$C37*F37/100 -> 0 | H37: 2.27 | L37: =$H37*K37/100 -> 0 | M37: 2.21 | Q37: =$M37*P37/100 -> 0 | R37: 1.44 | V37: =$R37*U37/100 -> 0 | W37: 0.17 | AA37: =$W37*Z37/100 -> 0 | AB37: 0.27 | AF37: =$AB37*AE37/100 -> 0 | AG37: 0.34 | AK37: =$AG37*AJ37/100 -> 0 | AL37: 0.36 | AP37: =$AL37*AO37/100 -> 0
B38: 4.12 Metal sheet roofing with sand coating on wood (Imported) | C38: 3.55 | G38: =$C38*F38/100 -> 0 | H38: 4.13 | L38: =$H38*K38/100 -> 0 | M38: 4.59 | Q38: =$M38*P38/100 -> 0 | R38: 5.63 | V38: =$R38*U38/100 -> 0 | W38: 4.38 | AA38: =$W38*Z38/100 -> 0 | AB38: 24.05 | AF38: =$AB38*AE38/100 -> 0 | AG38: 9.57 | AK38: =$AG38*AJ38/100 -> 0 | AL38: 8.57 | AP38: =$AL38*AO38/100 -> 0
B39: 4.13 Metal sheet roofing with sand coating on wood (local) | C39: 2.21 | G39: =$C39*F39/100 -> 0 | H39: 3.24 | L39: =$H39*K39/100 -> 0 | M39: 3.59 | Q39: =$M39*P39/100 -> 0 | R39: 4.4 | V39: =$R39*U39/100 -> 0 | W39: 3.43 | AA39: =$W39*Z39/100 -> 0 | AB39: 18.83 | AF39: =$AB39*AE39/100 -> 0 | AG39: 7.49 | AK39: =$AG39*AJ39/100 -> 0 | AL39: 6.71 | AP39: =$AL39*AO39/100 -> 0
B40: 4.14 Metal sheet roofing with sand coating on steel (Imported) | C40: 4.79 | G40: =$C40*F40/100 -> 0 | H40: 2.69 | L40: =$H40*K40/100 -> 0 | M40: 2.98 | Q40: =$M40*P40/100 -> 0 | R40: 3.66 | V40: =$R40*U40/100 -> 0 | W40: 2.85 | AA40: =$W40*Z40/100 -> 0 | AB40: 15.65 | AF40: =$AB40*AE40/100 -> 0 | AG40: 6.23 | AK40: =$AG40*AJ40/100 -> 0 | AL40: 5.57 | AP40: =$AL40*AO40/100 -> 0
B41: 4.15 Metal sheet roofing with sand coating on steel (local) | C41: 2.98 | G41: =$C41*F41/100 -> 0 | H41: 2.1 | L41: =$H41*K41/100 -> 0 | M41: 2.34 | Q41: =$M41*P41/100 -> 0 | R41: 2.86 | V41: =$R41*U41/100 -> 0 | W41: 2.23 | AA41: =$W41*Z41/100 -> 0 | AB41: 12.25 | AF41: =$AB41*AE41/100 -> 0 | AG41: 4.87 | AK41: =$AG41*AJ41/100 -> 0 | AL41: 4.36 | AP41: =$AL41*AO41/100 -> 0
...

Sheet Multi-Purposed halls
A2: ITEM NO. | B2: Building components
C3: H | F3: <= | G3: 4 | H3: = | K3: 4.5 | L3: = | O3: 5.5 | P3: = | S3: 6.5 | V3: = | W3: 7.5 | Z3: = | AA3: 8.5 | AD3: = | AE3: 10.5 | AH3: = | AI3: 11.5
A4: 1 | B4: Foundation | C4: Factors | D4: Max | E4: Min | H4: Max | I4: Min | L4: Max | M4: Min | P4: Max | Q4: Min | T4: Max | U4: Min | X4: Max | Y4: Min | AB4: Max | AC4: Min | AF4: Max | AG4: Min
B5: 1.1 Foundation only earthwork | C5: 0.22 | D5: =MAX(C5:C16) -> 4.2 | E5: =MIN(C5:C16) -> 0.22 | G5: =$C5*F5/100 -> 0 | H5: =MAX(C5:C16) -> 4.2 | I5: =MIN(C5:C16) -> 0.22 | K5: =$C5*H5/100 -> 0.00924 | L5: 4.2 | M5: 0.22 | O5: =C5*N5/100 -> 0 | P5: 4.2 | Q5: 0.22 | S5: =$C5*P5/100 -> 0.00924 | T5: 4.2 | U5: 0.22 | W5: =$C5*V5/100 -> 0 | X5: 4.2 | Y5: 0.22 | AA5: =$C5*Z5/100 -> 0 | AB5: 4.2 | AC5: 0.22 | AE5: =$C5*AD5/100 -> 0 | AF5: =MAX(C5:C16) -> 4.2 | AG5: =MIN(C5:C16) -> 0.22 | AI5: =$C5*AH5/100 -> 0
B6: 1.2 a. Earthwortk and masnory | C6: 0.69 | G6: =$C6*F6/100 -> 0 | K6: =$C6*H6/100 -> 0 | O6: =$C6*N6/100 -> 0 | S6: =$C6*P6/100 -> 0 | W6: =$C6*V6/100 -> 0 | AA6: =$C6*Z6/100 -> 0 | AE6: =$C6*AD6/100 -> 0 | AI6: =$C6*AH6/100 -> 0
B7: 1.2 b. AGL and BGL
B8: 1.3 Foundation work in | C8: 2 | G8: =$C8*F8/100 -> 0 | K8: =$C8*H8/100 -> 0 | O8: =$C8*N8/100 -> 0 | S8: =$C8*P8/100 -> 0 | W8: =$C8*V8/100 -> 0 | AA8: =$C8*Z8/100 -> 0 | AE8: =$C8*AD8/100 -> 0 | AI8: =$C8*AH8/100 -> 0
B9: 1.3a. Earthwork
B10: 1.3b. Hard rock
B11: 1.3c. Mass concrete floor slab
B12: 1.3d. R.C grade beam
B13: 1.3e. Masnory BGL and AGL
B14: 1.4 As item No.3 above but with R.C floor slab | C14: 2.87 | G14: =$C14*F14/100 -> 0 | K14: =$C14*H14/100 -> 0 | O14: =$C14*N14/100 -> 0 | S14: =$C14*P14/100 -> 0 | W14: =$C14*V14/100 -> 0 | AA14: =$C14*Z14/100 -> 0 | AE14: =$C14*AD14/100 -> 0 | AI14: =$C14*AH14/100 -> 0
B15: 1.5 As item no 4 above but with R.C footing and foundation column | C15: 3.43 | G15: =$C15*F15/100 -> 0 | K15: =$C15*H15/100 -> 0 | N15: 100 | O15: =$C15*N15/100 -> 3.43 | S15: =$C15*P15/100 -> 0 | W15: =$C15*V15/100 -> 0 | AA15: =$C15*Z15/100 -> 0 | AE15: =$C15*AD15/100 -> 0 | AI15: =$C15*AH15/100 -> 0
B16: 1.6 As item no 5 above but for R.C roof slab | C16: 4.2 | O16: =$C16*N16/100 -> 0
A17: 2 | B17: Structure | G17: =$C17*F17/100 -> 0 | K17: =$C17*H17/100 -> 0 | O17: =$C17*N17/100 -> 0 | S17: =$C17*P17/100 -> 0 | W17: =$C17*V17/100 -> 0 | AA17: =$C17*Z17/100 -> 0 | AE17: =$C17*AD17/100 -> 0 | AI17: =$C17*AH17/100 -> 0
B18: 2.1 .R.C structure (Elevation colums and tie beam) | C18: 1.38 | D18: =MAX(C18:C20) -> 10.76 | E18: =MIN(C18:C20) -> 1.38 | G18: =$C18*F18/100 -> 0 | H18: =MAX(C18:C20) -> 10.76 | I18: =MIN(C18:C20) -> 1.38 | K18: =$C18*H18/100 -> 0.148488 | L18: 10.76 | M18: 1.38 | N18: 100 | O18: =$C18*N18/100 -> 1.38 | P18: 10.76 | Q18: 1.38 | S18: =$C18*P18/100 -> 0.148488 | T18: 10.76 | U18: 1.38 | W18: =$C18*V18/100 -> 0 | X18: 10.76 | Y18: 1.38 | AA18: =$C18*Z18/100 -> 0 | AB18: 10.76 | AC18: 1.38 | AE18: =$C18*AD18/100 -> 0 | AF18: =MAX(C18:C20) -> 10.76 | AG18: =MIN(C18:C20) -> 1.38 | AI18: =$C18*AH18/100 -> 0
B19: 2.2 As item no.2 above but for R.C roof slab | C19: 2.37 | G19: =$C19*F19/100 -> 0 | K19: =$C19*H19/100 -> 0 | O19: =$C19*N19/100 -> 0 | S19: =$C19*P19/100 -> 0 | W19: =$C19*V19/100 -> 0 | AA19: =$C19*Z19/100 -> 0 | AE19: =$C19*AD19/100 -> 0 | AI19: =$C19*AH19/100 -> 0
B20: 2.3 Steel structure (R.H.S) | C20: 10.76 | G20: =$C20*F20/100 -> 0 | K20: =$C20*H20/100 -> 0 | O20: =$C20*N20/100 -> 0 | S20: =$C20*P20/100 -> 0 | W20: =$C20*V20/100 -> 0 | AA20: =$C20*Z20/100 -> 0 | AE20: =$C20*AD20/100 -> 0 | AI20: =$C20*AH20/100 -> 0
A21: 3 | B21: Block Work | G21: =$C21*F21/100 -> 0 | K21: =$C21*H21/100 -> 0 | O21: =$C21*N21/100 -> 0 | S21: =$C21*P21/100 -> 0 | W21: =$C21*V21/100 -> 0 | AA21: =$C21*Z21/100 -> 0 | AE21: =$C21*AD21/100 -> 0 | AI21: =$C21*AH21/100 -> 0
B22: 3.1 Internal | G22: =$C22*F22/100 -> 0 | K22: =$C22*H22/100 -> 0 | O22: =$C22*N22/100 -> 0 | S22: =$C22*P22/100 -> 0 | W22: =$C22*V22/100 -> 0 | AA22: =$C22*Z22/100 -> 0 | AE22: =$C22*AD22/100 -> 0 | AI22: =$C22*AH22/100 -> 0
B23: 3.1. see the methodology disscused on page 15 | G23: =$C23*F23/100 -> 0 | K23: =$C23*H23/100 -> 0 | O23: =$C23*N23/100 -> 0 | S23: =$C23*P23/100 -> 0 | W23: =$C23*V23/100 -> 0 | AA23: =$C23*Z23/100 -> 0 | AE23: =$C23*AD23/100 -> 0 | AI23: =$C23*AH23/100 -> 0
B24: 3.2 External | G24: =$C24*F24/100 -> 0 | K24: =$C24*H24/100 -> 0 | O24: =$C24*N24/100 -> 0 | S24: =$C24*P24/100 -> 0 | W24: =$C24*V24/100 -> 0 | AA24: =$C24*Z24/100 -> 0 | AE24: =$C24*AD24/100 -> 0 | AI24: =$C24*AH24/100 -> 0
B25: 3.2.1 Mud | C25: 0.26 | D25: =MAX(C25:C33) -> 2.42 | E25: =MIN(C25:C33) -> 0.26 | G25: =$C25*F25/100 -> 0 | H25: =MAX(C25:C33) -> 2.42 | I25: =MIN(C25:C33) -> 0.26 | K25: =$C25*H25/100 -> 0.006292 | L25: 2.42 | M25: 0.26 | O25: =$C25*N25/100 -> 0 | P25: 2.42 | Q25: 0.26 | S25: =$C25*P25/100 -> 0.006292 | T25: 2.42 | U25: 0.26 | W25: =$C25*V25/100 -> 0 | X25: 2.42 | Y25: 0.26 | AA25: =$C25*Z25/100 -> 0 | AB25: 2.42 | AC25: 0.26 | AE25: =$C25*AD25/100 -> 0 | AF25: =MAX(C25:C33) -> 2.42 | AG25: =MIN(C25:C33) -> 0.26 | AI25: =$C25*AH25/100 -> 0
B26: 3.2.2 CIS G-28 | C26: 0.52 | G26: =$C26*F26/100 -> 0 | K26: =$C26*H26/100 -> 0 | O26: =$C26*N26/100 -> 0 | S26: =$C26*P26/100 -> 0 | W26: =$C26*V26/100 -> 0 | AA26: =$C26*Z26/100 -> 0 | AE26: =$C26*AD26/100 -> 0 | AI26: =$C26*AH26/100 -> 0
B27: 3.2.3 CIS G-30 | C27: 0.38 | G27: =$C27*F27/100 -> 0 | K27: =$C27*H27/100 -> 0 | O27: =$C27*N27/100 -> 0 | S27: =$C27*P27/100 -> 0 | W27: =$C27*V27/100 -> 0 | AA27: =$C27*Z27/100 -> 0 | AE27: =$C27*AD27/100 -> 0 | AI27: =$C27*AH27/100 -> 0
B28: 3.2.4 CIS G-32 | C28: 0.4 | G28: =$C28*F28/100 -> 0 | K28: =$C28*H28/100 -> 0 | O28: =$C28*N28/100 -> 0 | S28: =$C28*P28/100 -> 0 | W28: =$C28*V28/100 -> 0 | AA28: =$C28*Z28/100 -> 0 | AE28: =$C28*AD28/100 -> 0 | AI28: =$C28*AH28/100 -> 0
B29: 3.2.5 EGA on steel | C29: 0.99 | G29: =$C29*F29/100 -> 0 | K29: =$C29*H29/100 -> 0 | O29: =$C29*N29/100 -> 0 | S29: =$C29*P29/100 -> 0 | W29: =$C29*V29/100 -> 0 | AA29: =$C29*Z29/100 -> 0 | AE29: =$C29*AD29/100 -> 0 | AI29: =$C29*AH29/100 -> 0
B30: 3.2.6 HCB 20 cm thick | C30: 0.38 | G30: =$C30*F30/100 -> 0 | K30: =$C30*H30/100 -> 0 | N30: 100 | O30: =$C30*N30/100 -> 0.38 | S30: =$C30*P30/100 -> 0 | W30: =$C30*V30/100 -> 0 | AA30: =$C30*Z30/100 -> 0 | AE30: =$C30*AD30/100 -> 0 | AI30: =$C30*AH30/100 -> 0
B31: 3.2.7 Brick 25cm thick | C31: 2.42 | G31: =$C31*F31/100 -> 0 | K31: =$C31*H31/100 -> 0 | O31: =$C31*N31/100 -> 0 | S31: =$C31*P31/100 -> 0 | W31: =$C31*V31/100 -> 0 | AA31: =$C31*Z31/100 -> 0 | AE31: =$C31*AD31/100 -> 0 | AI31: =$C31*AH31/100 -> 0
B32: 3.2.8 stone 40cm thick | C32: 1.63 | G32: =$C32*F32/100 -> 0 | K32: =$C32*H32/100 -> 0 | O32: =$C32*N32/100 -> 0 | S32: =$C32*P32/100 -> 0 | W32: =$C32*V32/100 -> 0 | AA32: =$C32*Z32/100 -> 0 | AE32: =$C32*AD32/100 -> 0 | AI32: =$C32*AH32/100 -> 0
B33: 3.2.9 stone 50cm thick | C33: 2.19 | G33: =$C33*F33/100 -> 0 | K33: =$C33*H33/100 -> 0 | O33: =$C33*N33/100 -> 0 | S33: =$C33*P33/100 -> 0 | W33: =$C33*V33/100 -> 0 | AA33: =$C33*Z33/100 -> 0 | AE33: =$C33*AD33/100 -> 0 | AI33: =$C33*AH33/100 -> 0
B34: 3.2.10 Alumimium | C34: 0 | G34: =$C34*F34/100 -> 0 | K34: =$C34*H34/100 -> 0 | O34: =$C34*N34/100 -> 0 | S34: =$C34*P34/100 -> 0 | W34: =$C34*V34/100 -> 0 | AA34: =$C34*Z34/100 -> 0 | AE34: =$C34*AD34/100 -> 0 | AI34: =$C34*AH34/100 -> 0
A35: 4 | B35: Roofing | G35: =$C35*F35/100 -> 0 | K35: =$C35*H35/100 -> 0 | O35: =$C35*N35/100 -> 0 | S35: =$C35*P35/100 -> 0 | W35: =$C35*V35/100 -> 0 | AA35: =$C35*Z35/100 -> 0 | AE35: =$C35*AD35/100 -> 0 | AI35: =$C35*AH35/100 -> 0
B36: 4.1 CIS G-32 on wood | C36: 4.29 | D36: =MAX(C36:C44) -> 16.22 | E36: =MIN(C36:C44) -> 4.14 | G36: =$C36*F36/100 -> 0 | H36: =MAX(C36:C44) -> 16.22 | I36: =MIN(C36:C44) -> 4.14 | K36: =$C36*H36/100 -> 0.695838 | L36: 16.22 | M36: 4.14 | O36: =$C36*N36/100 -> 0 | P36: 16.22 | Q36: 4.14 | S36: =$C36*P36/100 -> 0.695838 | T36: 16.22 | U36: 4.14 | W36: =$C36*V36/100 -> 0 | X36: 16.22 | Y36: 4.14 | AA36: =$C36*Z36/100 -> 0 | AB36: 16.22 | AC36: 4.14 | AE36: =$C36*AD36/100 -> 0 | AF36: =MAX(C36:C44) -> 16.22 | AG36: =MIN(C36:C44) -> 4.14 | AI36: =$C36*AH36/100 -> 0
B37: 4.2 CIS G-30 on wood | C37: 4.41 | G37: =$C37*F37/100 -> 0 | K37: =$C37*H37/100 -> 0 | O37: =$C37*N37/100 -> 0 | S37: =$C37*P37/100 -> 0 | W37: =$C37*V37/100 -> 0 | AA37: =$C37*Z37/100 -> 0 | AE37: =$C37*AD37/100 -> 0 | AI37: =$C37*AH37/100 -> 0
B38: 4.3 CIS G-28 on wood | C38: 4.71 | G38: =$C38*F38/100 -> 0 | K38: =$C38*H38/100 -> 0 | O38: =$C38*N38/100 -> 0 | S38: =$C38*P38/100 -> 0 | W38: =$C38*V38/100 -> 0 | AA38: =$C38*Z38/100 -> 0 | AE38: =$C38*AD38/100 -> 0 | AI38: =$C38*AH38/100 -> 0
B39: 4.4 EGA on steel | C39: 15.25 | G39: =$C39*F39/100 -> 0 | K39: =$C39*H39/100 -> 0 | O39: =$C39*N39/100 -> 0 | S39: =$C39*P39/100 -> 0 | W39: =$C39*V39/100 -> 0 | AA39: =$C39*Z39/100 -> 0 | AE39: =$C39*AD39/100 -> 0 | AI39: =$C39*AH39/100 -> 0
B40: 4.5 EGA on wood | C40: 9.98 | G40: =$C40*F40/100 -> 0 | K40: =$C40*H40/100 -> 0 | O40: =$C40*N40/100 -> 0 | S40: =$C40*P40/100 -> 0 | W40: =$C40*V40/100 -> 0 | AA40: =$C40*Z40/100 -> 0 | AE40: =$C40*AD40/100 -> 0 | AI40: =$C40*AH40/100 -> 0
B41: 4.6 CIS G-28 on steel | C41: 16.22 | G41: =$C41*F41/100 -> 0 | K41: =$C41*H41/100 -> 0 | N41: 100 | O41: =$C41*N41/100 -> 16.22 | S41: =$C41*P41/100 -> 0 | W41: =$C41*V41/100 -> 0 | AA41: =$C41*Z41/100 -> 0 | AE41: =$C41*AD41/100 -> 0 | AI41: =$C41*AH41/100 -> 0
...

Sheet Plot grade
B1: No | D1: Plot grade
B2: 1 | D2: 1-1b
B3: 2 | D3: 1-1a
B4: 3 | D4: 1-1
B5: 4 | D5: 1-2
B6: 5 | D6: 2-1
B7: 6 | D7: 1-3
B8: 7 | D8: 2-2
B9: 8 | D9: 3-1
B10: 9 | D10: 2-3
B11: 10 | D11: 3-2
B12: 11 | D12: 4-1
B13: 12 | D13: 3-3
B14: 13 | D14: 4-2
B15: 14 | D15: 4-3 | G15: 1000097015264
B16: 15 | D16: 4-4 | G16: 1000059902702 | H16: hawine mulugeta
D18: 1-1b | F18: 1-1a | H18: 1-1 | J18: 1-2 | L18: 2-1 | N18: 1-3 | P18: 2-2 | R18: 3-1 | T18: 2-3 | V18: 3-2 | X18: 4-1 | Z18: 3-3 | AB18: 4-2 | AD18: 4-3 | AF18: 4-4
D19: 1 | F19: 2 | H19: 3 | J19: 4 | L19: 5 | N19: 6 | P19: 7 | R19: 8 | T19: 9 | V19: 10 | X19: 11 | Z19: 12 | AB19: 13 | AD19: 14 | AF19: 15
B20: 0-100 | C20: 100 | D20: 67844 | E20: =$C$20*D20 -> 6784400 | F20: 44355 | G20: =$C$20*F20 -> 4435500 | H20: 35523 | I20: =$C$20*H20 -> 3552300 | J20: 30912 | K20: =$C$20*J20 -> 3091200 | L20: 26368 | M20: =$C$20*L20 -> 2636800 | N20: 23599 | O20: =$C$20*N20 -> 2359900 | P20: 21576 | Q20: =$C$20*P20 -> 2157600 | R20: 20351 | S20: =$C$20*R20 -> 2035100 | T20: 17283 | U20: =$C$20*T20 -> 1728300 | V20: 16267 | W20: =$C$20*V20 -> 1626700 | X20: 15202 | Y20: =$C$20*X20 -> 1520200 | Z20: 14559 | AA20: =$C$20*Z20 -> 1455900 | AB20: 14168 | AC20: =$C$20*AB20 -> 1416800 | AD20: 13275 | AE20: =$C$20*AD20 -> 1327500 | AF20: 126888
B21: 101-200 | C21: 200 | D21: 62975 | E21: =E20+((C21-C20)*D21) -> 13081900 | F21: 43454 | G21: =G20+((C21-C20)*F21) -> 8780900 | H21: 345992 | I21: =I20+((C21-C20)*H21) -> 38151500 | J21: 30521 | K21: =K20+((C21-C20)*J21) -> 6143300 | L21: 26031 | M21: =M20+((C21-C20)*L21) -> 5239900 | N21: 23069 | O21: =O20+((C21-C20)*N21) -> 4666800 | P21: 20104 | Q21: =Q20+((C21-C20)*P21) -> 4168000 | R21: 18420 | S21: =S20+((C21-C20)*R21) -> 3877100 | T21: 17082 | U21: =U20+((C21-C20)*T21) -> 3436500 | V21: 15588 | W21: =W20+((C21-C20)*V21) -> 3185500 | X21: 14625 | Y21: =Y20+((C21-C20)*X21) -> 2982700 | Z21: 14104 | AA21: =AA20+((C21-C20)*Z21) -> 2866300 | AB21: 13800 | AC21: =AC20+((C21-C20)*AB21) -> 2796800 | AD21: 12537 | AE21: =AE20+((C21-C20)*AD21) -> 2581200 | AF21: 11933
B22: 201-300 | C22: 300 | D22: 58106 | E22: =E21+((C22-C21)*D22) -> 18892500 | F22: 42553 | G22: =G21+((C22-C21)*F22) -> 13036200 | H22: 34261 | I22: =I21+((C22-C21)*H22) -> 41577600 | J22: 30130 | K22: =K21+((C22-C21)*J22) -> 9156300 | L22: 25694 | M22: =M21+((C22-C21)*L22) -> 7809300 | N22: 22539 | O22: =O21+((C22-C21)*N22) -> 6920700 | P22: 19022 | Q22: =Q21+((C22-C21)*P22) -> 6070200 | R22: 17315 | S22: =S21+((C22-C21)*R22) -> 5608600 | T22: 16898 | U22: =U21+((C22-C21)*T22) -> 5126300 | V22: 14991 | W22: =W21+((C22-C21)*V22) -> 4684600 | X22: 14128 | Y22: =Y21+((C22-C21)*X22) -> 4395500 | Z22: 13518 | AA22: =AA21+((C22-C21)*Z22) -> 4218100 | AB22: 13622 | AC22: =AC21+((C22-C21)*AB22) -> 4159000 | AD22: 11799 | AE22: =AE21+((C22-C21)*AD22) -> 3761100 | AF22: 11318
B23: 301-400 | C23: 400 | D23: 54919 | E23: =E22+((C23-C22)*D23) -> 24384400 | F23: 41705 | G23: =G22+((C23-C22)*F23) -> 17206700 | H23: 33805 | I23: =I22+((C23-C22)*H23) -> 44958100 | J23: 29745 | K23: =K22+((C23-C22)*J23) -> 12130800 | L23: 25445 | M23: =M22+((C23-C22)*L23) -> 10353800 | N23: 22284 | O23: =O22+((C23-C22)*N23) -> 9149100 | P23: 18829 | Q23: =Q22+((C23-C22)*P23) -> 7953100 | R23: 17146 | S23: =S22+((C23-C22)*R23) -> 7323200 | T23: 16726 | U23: =U22+((C23-C22)*T23) -> 6798900 | V23: 14541 | W23: =W22+((C23-C22)*V23) -> 6138700 | X23: 13986 | Y23: =Y22+((C23-C22)*X23) -> 5794100 | Z23: 13385 | AA23: =AA22+((C23-C22)*Z23) -> 5556600 | AB23: 13487 | AC23: =AC22+((C23-C22)*AB23) -> 5507700 | AD23: 11644 | AE23: =AE22+((C23-C22)*AD23) -> 4925500 | AF23: 11197
B24: 401-500 | C24: 500 | D24: 54358 | E24: =E23+((C24-C23)*D24) -> 29820200 | F24: 41283 | G24: =G23+((C24-C23)*F24) -> 21335000 | H24: 33463 | I24: =I23+((C24-C23)*H24) -> 48304400 | J24: 29444 | K24: =K23+((C24-C23)*J24) -> 15075200 | L24: 25195 | M24: =M23+((C24-C23)*L24) -> 12873300 | N24: 22048 | O24: =O23+((C24-C23)*N24) -> 11353900 | P24: 18636 | Q24: =Q23+((C24-C23)*P24) -> 9816700 | R24: 16977 | S24: =S23+((C24-C23)*R24) -> 9020900 | T24: 16554 | U24: =U23+((C24-C23)*T24) -> 8454300 | V24: 14691 | W24: =W23+((C24-C23)*V24) -> 7607800 | X24: 13844 | Y24: =Y23+((C24-C23)*X24) -> 7178500 | Z24: 13252 | AA24: =AA23+((C24-C23)*Z24) -> 6881800 | AB24: 13352 | AC24: =AC23+((C24-C23)*AB24) -> 6842900 | AD24: 11513 | AE24: =AE23+((C24-C23)*AD24) -> 6076800 | AF24: 11076
B25: 501-600 | C25: 600 | D25: 20732 | E25: =E24+((C25-C24)*D25) -> 31893400 | F25: 18639 | G25: =G24+((C25-C24)*F25) -> 23198900 | H25: 17813 | I25: =I24+((C25-C24)*H25) -> 50085700 | J25: 18643 | K25: =K24+((C25-C24)*J25) -> 16939500 | L25: 16694 | M25: =M24+((C25-C24)*L25) -> 14542700 | N25: 14505 | O25: =O24+((C25-C24)*N25) -> 12804400 | P25: 14141 | Q25: =Q24+((C25-C24)*P25) -> 11230800 | R25: 12909 | S25: =S24+((C25-C24)*R25) -> 10311800 | T25: 11677 | U25: =U24+((C25-C24)*T25) -> 9622000 | V25: 11071 | W25: =W24+((C25-C24)*V25) -> 8714900 | X25: 10703 | Y25: =Y24+((C25-C24)*X25) -> 8248800 | Z25: 9812 | AA25: =AA24+((C25-C24)*Z25) -> 7863000 | AB25: 7311 | AC25: =AC24+((C25-C24)*AB25) -> 7574000 | AD25: 7239 | AE25: =AE24+((C25-C24)*AD25) -> 6800700 | AF25: 6212
B26: 601-700 | C26: 700 | D26: 20477 | E26: =E25+((C26-C25)*D26) -> 33941100 | F26: 18351 | G26: =G25+((C26-C25)*F26) -> 25034000 | H26: 17591 | I26: =I25+((C26-C25)*H26) -> 51844800 | J26: 16832 | K26: =K25+((C26-C25)*J26) -> 18622700 | L26: 16408 | M26: =M25+((C26-C25)*L26) -> 16183500 | N26: 14318 | O26: =O25+((C26-C25)*N26) -> 14236200 | P26: 13946 | Q26: =Q25+((C26-C25)*P26) -> 12625400 | R26: 12612 | S26: =S25+((C26-C25)*R26) -> 11573000 | T26: 11545 | U26: =U25+((C26-C25)*T26) -> 10776500 | V26: 11006 | W26: =W25+((C26-C25)*V26) -> 9815500 | X26: 10551 | Y26: =Y25+((C26-C25)*X26) -> 9303900 | Z26: 9731 | AA26: =AA25+((C26-C25)*Z26) -> 8836100 | AB26: 7221 | AC26: =AC25+((C26-C25)*AB26) -> 8296100 | AD26: 7215 | AE26: =AE25+((C26-C25)*AD26) -> 7522200 | AF26: 6167
B27: 701-800 | C27: 800 | D27: 20213 | E27: =E26+((C27-C26)*D27) -> 35962400 | F27: 18501 | G27: =G26+((C27-C26)*F27) -> 26884100 | H27: 18739 | I27: =I26+((C27-C26)*H27) -> 53718700 | J27: 18220 | K27: =K26+((C27-C26)*J27) -> 20444700 | L27: 16394 | M27: =M26+((C27-C26)*L27) -> 17822900 | N27: 14154 | O27: =O26+((C27-C26)*N27) -> 15651600 | P27: 13967 | Q27: =Q26+((C27-C26)*P27) -> 14022100 | R27: 13388 | S27: =S26+((C27-C26)*R27) -> 12911800 | T27: 12804 | U27: =U26+((C27-C26)*T27) -> 12056900 | V27: 12348 | W27: =W26+((C27-C26)*V27) -> 11050300 | X27: 11897 | Y27: =Y26+((C27-C26)*X27) -> 10493600 | Z27: 10044 | AA27: =AA26+((C27-C26)*Z27) -> 9840500 | AB27: 8936 | AC27: =AC26+((C27-C26)*AB27) -> 9189700 | AD27: 7184 | AE27: =AE26+((C27-C26)*AD27) -> 8240600 | AF27: 6118
B28: 801-900 | C28: 900 | D28: 25258 | E28: =E27+((C28-C27)*D28) -> 38488200 | F28: 23415 | G28: =G27+((C28-C27)*F28) -> 29225600 | H28: 23415 | I28: =I27+((C28-C27)*H28) -> 56060200 | J28: 22656 | K28: =K27+((C28-C27)*J28) -> 22710300 | L28: 21508 | M28: =M27+((C28-C27)*L28) -> 19973700 | N28: 20158 | O28: =O27+((C28-C27)*N28) -> 17667400 | P28: 20107 | Q28: =Q27+((C28-C27)*P28) -> 16032800 | R28: 19988 | S28: =S27+((C28-C27)*R28) -> 14910600 | T28: 19861 | U28: =U27+((C28-C27)*T28) -> 14043000 | V28: 19614 | W28: =W27+((C28-C27)*V28) -> 13011700 | X28: 19382 | Y28: =Y27+((C28-C27)*X28) -> 12431800 | Z28: 16111 | AA28: =AA27+((C28-C27)*Z28) -> 11451600 | AB28: 14026 | AC28: =AC27+((C28-C27)*AB28) -> 10592300 | AD28: 7158 | AE28: =AE27+((C28-C27)*AD28) -> 8956400 | AF28: 6062
B29: 901-1000 | C29: 1000 | D29: 25001 | E29: =E28+((C29-C28)*D29) -> 40988300 | F29: 23190 | G29: =G28+((C29-C28)*F29) -> 31544600 | H29: 23190 | I29: =I28+((C29-C28)*H29) -> 58379200 | J29: 23332 | K29: =K28+((C29-C28)*J29) -> 25043500 | L29: 21968 | M29: =M28+((C29-C28)*L29) -> 22170500 | N29: 21622 | O29: =O28+((C29-C28)*N29) -> 19829600 | P29: 20783 | Q29: =Q28+((C29-C28)*P29) -> 18111100 | R29: 20366 | S29: =S28+((C29-C28)*R29) -> 16947200 | T29: 19943 | U29: =U28+((C29-C28)*T29) -> 16037300 | V29: 19871 | W29: =W28+((C29-C28)*V29) -> 14998800 | X29: 19249 | Y29: =Y28+((C29-C28)*X29) -> 14356700 | Z29: 18181 | AA29: =AA28+((C29-C28)*Z29) -> 13269700 | AB29: 16066 | AC29: =AC28+((C29-C28)*AB29) -> 12198900 | AD29: 7130 | AE29: =AE28+((C29-C28)*AD29) -> 9669400 | AF29: 6011
B30: 1001-1100 | C30: 1100 | D30: 24751 | E30: =E29+((C30-C29)*D30) -> 43463400 | F30: 22575 | G30: =G29+((C30-C29)*F30) -> 33802100 | H30: 21758 | I30: =I29+((C30-C29)*H30) -> 60555000 | J30: 21064 | K30: =K29+((C30-C29)*J30) -> 27149900 | L30: 20168 | M30: =M29+((C30-C29)*L30) -> 24187300 | N30: 19825 | O30: =O29+((C30-C29)*N30) -> 21812100 | P30: 18009 | Q30: =Q29+((C30-C29)*P30) -> 19912000 | R30: 17165 | S30: =S29+((C30-C29)*R30) -> 18663700 | T30: 16316 | U30: =U29+((C30-C29)*T30) -> 17668900 | V30: 7699 | W30: =W29+((C30-C29)*V30) -> 15768700 | X30: 7486 | Y30: =Y29+((C30-C29)*X30) -> 15105300 | Z30: 7412 | AA30: =AA29+((C30-C29)*Z30) -> 14010900 | AB30: 7340 | AC30: =AC29+((C30-C29)*AB30) -> 12932900 | AD30: 6600 | AE30: =AE29+((C30-C29)*AD30) -> 10329400 | AF30: 5966
B31: 1101-1200 | C31: 1200 | D31: 26991 | E31: =E30+((C31-C30)*D31) -> 46162500 | F31: 25943 | G31: =G30+((C31-C30)*F31) -> 36396400 | H31: 21050 | I31: =I30+((C31-C30)*H31) -> 62660000 | J31: 20390 | K31: =K30+((C31-C30)*J31) -> 29188900 | L31: 19852 | M31: =M30+((C31-C30)*L31) -> 26172500 | N31: 19488 | O31: =O30+((C31-C30)*N31) -> 23760900 | P31: 17803 | Q31: =Q30+((C31-C30)*P31) -> 21692300 | R31: 16905 | S31: =S30+((C31-C30)*R31) -> 20354200 | T31: 15843 | U31: =U30+((C31-C30)*T31) -> 19253200 | V31: 7623 | W31: =W30+((C31-C30)*V31) -> 16531000 | X31: 7335 | Y31: =Y30+((C31-C30)*X31) -> 15838800 | Z31: 7276 | AA31: =AA30+((C31-C30)*Z31) -> 14738500 | AB31: 7249 | AC31: =AC30+((C31-C30)*AB31) -> 13657800 | AD31: 6545 | AE31: =AE30+((C31-C30)*AD31) -> 10983900 | AF31: 5916
B32: 1201-1300 | C32: 1300 | D32: 26638 | E32: =E31+((C32-C31)*D32) -> 48826300 | F32: 25605 | G32: =G31+((C32-C31)*F32) -> 38956900 | H32: 17908 | I32: =I31+((C32-C31)*H32) -> 64450800 | J32: 17269 | K32: =K31+((C32-C31)*J32) -> 30915800 | L32: 16881 | M32: =M31+((C32-C31)*L32) -> 27860600 | N32: 16517 | O32: =O31+((C32-C31)*N32) -> 25412600 | P32: 15951 | Q32: =Q31+((C32-C31)*P32) -> 23287400 | R32: 16558 | S32: =S31+((C32-C31)*R32) -> 22010000 | T32: 15382 | U32: =U31+((C32-C31)*T32) -> 20791400 | V32: 7699 | W32: =W31+((C32-C31)*V32) -> 17300900 | X32: 7184 | Y32: =Y31+((C32-C31)*X32) -> 16557200 | Z32: 7148 | AA32: =AA31+((C32-C31)*Z32) -> 15453300 | AB32: 7099 | AC32: =AC31+((C32-C31)*AB32) -> 14367700 | AD32: 5361 | AE32: =AE31+((C32-C31)*AD32) -> 11520000 | AF32: 5875
... B44: 40001-70000 | C44: 70000 | D44: 4540 | E44: =E43+((C44-C43)*D44) -> 574677400 | F44: 4134 | G44: =G43+((C44-C43)*F44) -> 511702900 | H44: 4034 | I44: =I43+((C44-C43)*H44) -> 453592000 | J44: 3673 | K44: =K43+((C44-C43)*J44) -> 397844300 | L44: 3166 | M44: =M43+((C44-C43)*L44) -> 990523500 | N44: 2597 | O44: =O43+((C44-C43)*N44) -> 307058300 | P44: 2477 | Q44: =Q43+((C44-C43)*P44) -> 281272400 | R44: 2237 | S44: =S43+((C44-C43)*R44) -> 230181800 | T44: 1936 | U44: =U43+((C44-C43)*T44) -> 210368600 | V44: 1640 | W44: =W43+((C44-C43)*V44) -> 190544300 | X44: 1328 | Y44: =Y43+((C44-C43)*X44) -> 173690500 | Z44: 850 | AA44: =AA43+((C44-C43)*Z44) -> 151894500 | AB44: 715 | AC44: =AC43+((C44-C43)*AB44) -> 141740600 | AD44: 520 | AE44: =AE43+((C44-C43)*AD44) -> 87844900 | AF44: 547
B45: >70000 | D45: 2012 | E45: =E44+((C45-C44)*D45) -> 433837400 | F45: 1874 | G45: =G44+((C45-C44)*F45) -> 380522900 | H45: 1848 | I45: =I44+((C45-C44)*H45) -> 324232000 | J45: 1738 | K45: =K44+((C45-C44)*J45) -> 276184300 | L45: 1488 | M45: =M44+((C45-C44)*L45) -> 886363500 | N45: 1218 | O45: =O44+((C45-C44)*N45) -> 221798300 | P45: 1079 | Q45: =Q44+((C45-C44)*P45) -> 205742400 | R45: 1089 | S45: =S44+((C45-C44)*R45) -> 153951800 | T45: 707 | U45: =U44+((C45-C44)*T45) -> 160878600 | V45: 677 | W45: =W44+((C45-C44)*V45) -> 143154300 | X45: 641 | Y45: =Y44+((C45-C44)*X45) -> 128820500 | Z45: 401 | AA45: =AA44+((C45-C44)*Z45) -> 123824500 | AB45: 364 | AC45: =AC44+((C45-C44)*AB45) -> 116260600 | AD45: 361 | AE45: =AE44+((C45-C44)*AD45) -> 62574900 | AF45: 295
B48: Architectural
B49: Structural
B50: Electrical
B51: Sanitary
B52: Specification and Bill of quantity
B54: Water Supply & Drain Line
B55: Septic tank
...

Sheet Location
A6: Location value | I6: =31.5*16 -> 504
A7: Property location
A8: City | B8: A.A
A9: Sub city | B9: Nifas Silk
A10: Worda | B10: 2 | H10: 2720 | I10: 200 | J10: 200 | K10: =H10*J10 -> 544000
A11: Plot Area | B11: 220.9 | H11: 2040 | I11: 97.29 | J11: 131.7 | K11: =H11*J11 -> 268668
A12: Plot Grade | B12: 2-1 | I12: 200 | K12: =H12*J12 -> 0
A13: Location Value | B13: =IF(B12="1-1b",D48,IF(B12="1-1a",F48,IF(B12="1-1",H48,IF(B12="1-2",K48,IF(B12="2-1",M48,IF(B12="1-3",O48,IF(B12="2-2",Q48,IF(B12="3-1",S48,IF(B12="2-3",U48,IF(B12="3-2",W48,IF(B12="4-1",Y48,IF(B12="3-3",AA48,IF(B12="4-2",AC48,IF(B12="4-3",AE48,IF(B12="4-4",AG48))))))))))))))) -> 5776904.6 | I13: 200 | K13: =H13*J13 -> 0 | M13: =100*(K13+K14+K15+K16+K17) -> 0
A14: Total lease amount | I14: 200 | K14: =H14*J14 -> 0
A15: Paid up Lease amount | B15: 0 | I15: 500 | K15: =H15*J15 -> 0
A16: Remaining lease amount | B16: =IF(B14>1,B14-B15,"0") -> 0 | H16: =226*2.5 -> 565 | I16: 500 | K16: =H16*J16 -> 0
A17: Location Value | H17: =177*2.5 -> 442.5 | I17: 1000 | K17: =H17*J17 -> 0
A18: Location value in previous Estimation | I18: =SUM(I10:I17) -> 2897.29 | J18: =SUM(J10:J17) -> 331.7 | K18: =SUM(K10:K17) -> 812668 | L18: =SUM(L13:L17) -> 0 | R18: =B13-R19 -> 168304.6
A19: Location value Considered | B19: =K18 -> 812668 | R19: =(100*R22)+(100*R23)+(100*R24) -> 5608600 | AF19: =100*AF22+100*AF23 -> 2462100
C20: 1-1b | E20: 1-1a | G20: 1-1 | I20: 1-2 | L20: 2-1 | N20: 1-3 | P20: 2-2 | R20: 3-1 | T20: 2-3 | V20: 3-2 | X20: 4-1 | Z20: 3-3 | AB20: 4-2 | AD20: 4-3 | AF20: 4-4
C21: 1 | E21: 2 | G21: 3 | I21: 4 | L21: 5 | N21: 6 | P21: 7 | R21: 8 | T21: 9 | V21: 10 | X21: 11 | Z21: 12 | AB21: 13 | AD21: 14 | AF21: 15
A22: 0-100 | B22: 100 | C22: 67844 | D22: =$B$22*C22 -> 6784400 | E22: 44355 | F22: =$B$22*E22 -> 4435500 | G22: 35523 | H22: =$B$22*G22 -> 3552300 | I22: 30912 | K22: =$B$22*I22 -> 3091200 | L22: 26368 | M22: =$B$22*L22 -> 2636800 | N22: 23599 | O22: =$B$22*N22 -> 2359900 | P22: 21576 | Q22: =$B$22*P22 -> 2157600 | R22: 20351 | S22: =$B$22*R22 -> 2035100 | T22: 17283 | U22: =$B$22*T22 -> 1728300 | V22: 16267 | W22: =$B$22*V22 -> 1626700 | X22: 15202 | Y22: =$B$22*X22 -> 1520200 | Z22: 14559 | AA22: =$B$22*Z22 -> 1455900 | AB22: 14168 | AC22: =$B$22*AB22 -> 1416800 | AD22: 13275 | AE22: =$B$22*AD22 -> 1327500 | AF22: 12688 | AG22: =$B$22*AF22 -> 1268800
A23: 101-200 | B23: 200 | C23: 62975 | D23: =D22+((B23-B22)*C23) -> 13081900 | E23: 43454 | F23: =F22+((B23-B22)*E23) -> 8780900 | G23: 34892 | H23: =H22+((B23-B22)*G23) -> 7041500 | I23: 30521 | K23: =K22+((B23-B22)*I23) -> 6143300 | L23: 26031 | M23: =M22+((B23-B22)*L23) -> 5239900 | N23: 23069 | O23: =O22+((B23-B22)*N23) -> 4666800 | P23: 20104 | Q23: =Q22+((B23-B22)*P23) -> 4168000 | R23: 18420 | S23: =S22+((B23-B22)*R23) -> 3877100 | T23: 17082 | U23: =U22+((B23-B22)*T23) -> 3436500 | V23: 15588 | W23: =W22+((B23-B22)*V23) -> 3185500 | X23: 14625 | Y23: =Y22+((B23-B22)*X23) -> 2982700 | Z23: 14104 | AA23: =AA22+((B23-B22)*Z23) -> 2866300 | AB23: 13800 | AC23: =AC22+((B23-B22)*AB23) -> 2796800 | AD23: 12537 | AE23: =AE22+((B23-B22)*AD23) -> 2581200 | AF23: 11933 | AG23: =AG22+((B23-B22)*AF23) -> 2462100
A24: 201-300 | B24: 300 | C24: 58106 | D24: =D23+((B24-B23)*C24) -> 18892500 | E24: 42553 | F24: =F23+((B24-B23)*E24) -> 13036200 | G24: 34261 | H24: =H23+((B24-B23)*G24) -> 10467600 | I24: 30130 | K24: =K23+((B24-B23)*I24) -> 9156300 | L24: 25694 | M24: =M23+((B24-B23)*L24) -> 7809300 | N24: 22539 | O24: =O23+((B24-B23)*N24) -> 6920700 | P24: 19022 | Q24: =Q23+((B24-B23)*P24) -> 6070200 | R24: 17315 | S24: =S23+((B24-B23)*R24) -> 5608600 | T24: 16898 | U24: =U23+((B24-B23)*T24) -> 5126300 | V24: 14991 | W24: =W23+((B24-B23)*V24) -> 4684600 | X24: 14128 | Y24: =Y23+((B24-B23)*X24) -> 4395500 | Z24: 13518 | AA24: =AA23+((B24-B23)*Z24) -> 4218100 | AB24: 13622 | AC24: =AC23+((B24-B23)*AB24) -> 4159000 | AD24: 11799 | AE24: =AE23+((B24-B23)*AD24) -> 3761100 | AF24: 11318 | AG24: =AG23+((B24-B23)*AF24) -> 3593900
A25: 301-400 | B25: 400 | C25: 54919 | D25: =D24+((B25-B24)*C25) -> 24384400 | E25: 41705 | F25: =F24+((B25-B24)*E25) -> 17206700 | G25: 33805 | H25: =H24+((B25-B24)*G25) -> 13848100 | I25: 29745 | K25: =K24+((B25-B24)*I25) -> 12130800 | L25: 25445 | M25: =M24+((B25-B24)*L25) -> 10353800 | N25: 22284 | O25: =O24+((B25-B24)*N25) -> 9149100 | P25: 18829 | Q25: =Q24+((B25-B24)*P25) -> 7953100 | R25: 17146 | S25: =S24+((B25-B24)*R25) -> 7323200 | T25: 16726 | U25: =U24+((B25-B24)*T25) -> 6798900 | V25: 14541 | W25: =W24+((B25-B24)*V25) -> 6138700 | X25: 13986 | Y25: =Y24+((B25-B24)*X25) -> 5794100 | Z25: 13385 | AA25: =AA24+((B25-B24)*Z25) -> 5556600 | AB25: 13487 | AC25: =AC24+((B25-B24)*AB25) -> 5507700 | AD25: 11644 | AE25: =AE24+((B25-B24)*AD25) -> 4925500 | AF25: 11197 | AG25: =AG24+((B25-B24)*AF25) -> 4713600
